Workbook
Name SegmentaçãodeDados_Planta: #N/A
Name SegmentaçãodeDados_Status: #N/A

Sheet Base
A1: Conc | B1: GP | C1: Descrição | D1: Parque | E1: Planta | F1: LRR | G1: Estoque Parque | H1: Estoque Ok/Nok | I1: Quant. PO | J1: Previsão no Parque | K1: Mes/Ano | L1: Coluna4 | M1: Coluna3 | N1: Status | O1: Quant. Entregue | P1: Data entrega | Q1: Obs
A2: =_xlfn.CONCAT(B2,D2) -> GP127960B867 | B2: GP127960 | C2: GENERIC G9X ELECTRIC ROTATING JOINT STD | D2: B867 | E2: VSMIII | F2: 2 | G2: =IFERROR(VLOOKUP(A2,'Est. Parq.'!A:J,10,0),0) -> 1 | H2: =Tabela1[[#This Row],[Estoque Parque]]-Tabela1[[#This Row],[LRR]] -> -1 | I2: =SUMIF(SQVI!B:B,Base!A35,SQVI!V:V) -> 0 | J2: 46327 | K2: =UPPER(TEXT(Tabela1[[#This Row],[Previsão no Parque ]],"mmm/aaaa")) -> NOV/2026 | L2: =TEXT(Tabela1[[#This Row],[Previsão no Parque ]],"MMMM") -> novembro | M2: =TEXT(Tabela1[[#This Row],[Previsão no Parque ]],"AAAA") -> 2026 | N2: Pendente | O2: -2 | P2: 46234 | Q2: Verificando Bloco Norte e Delta 11 unids
A3: =_xlfn.CONCAT(B3,D3) -> GP131157B865 | B3: GP131157 | C3: COTTON CLOTHS PACKAGE | D3: B865 | E3: TERRA SANTA | F3: 50 | G3: =IFERROR(VLOOKUP(A3,'Est. Parq.'!A:J,10,0),0) -> 0 | H3: =Tabela1[[#This Row],[Estoque Parque]]-Tabela1[[#This Row],[LRR]] -> -50 | I3: =SUMIF(SQVI!B:B,Base!A38,SQVI!V:V) -> 2 | J3: 46296 | K3: =UPPER(TEXT(Tabela1[[#This Row],[Previsão no Parque ]],"mmm/aaaa")) -> OUT/2026 | L3: =TEXT(Tabela1[[#This Row],[Previsão no Parque ]],"MMMM") -> outubro | M3: =TEXT(Tabela1[[#This Row],[Previsão no Parque ]],"AAAA") -> 2026 | N3: Em rota | O3: 350 | P3: 46225
A4: =_xlfn.CONCAT(B4,D4) -> GP241858B832 | B4: GP241858 | C4: INDUCTIVE SENSOR M18 | D4: B832 | E4: UNIÃO DOS VENTOS (UDV) | F4: 2 | G4: =IFERROR(VLOOKUP(A4,'Est. Parq.'!A:J,10,0),0) -> 2 | H4: =Tabela1[[#This Row],[Estoque Parque]]-Tabela1[[#This Row],[LRR]] -> 0 | I4: =SUMIF(SQVI!B:B,Base!A44,SQVI!V:V) -> 750 | J4: 46388 | K4: =UPPER(TEXT(Tabela1[[#This Row],[Previsão no Parque ]],"mmm/aaaa")) -> JAN/2027 | L4: =TEXT(Tabela1[[#This Row],[Previsão no Parque ]],"MMMM") -> janeiro | M4: =TEXT(Tabela1[[#This Row],[Previsão no Parque ]],"AAAA") -> 2027 | N4: Pendente | O4: -1 | P4: 46188 | Q4: verificando Bloco Norte
A5: =_xlfn.CONCAT(B5,D5) -> GP249817B857 | B5: GP249817 | C5: FAN_JAS_FJ28082MAB | D5: B857 | E5: VSMII | F5: 2 | G5: =IFERROR(VLOOKUP(A5,'Est. Parq.'!A:J,10,0),0) -> 0 | H5: =Tabela1[[#This Row],[Estoque Parque]]-Tabela1[[#This Row],[LRR]] -> -2 | I5: =SUMIF(SQVI!B:B,Base!A47,SQVI!V:V) -> 0 | J5: 46296 | K5: =UPPER(TEXT(Tabela1[[#This Row],[Previsão no Parque ]],"mmm/aaaa")) -> OUT/2026 | L5: =TEXT(Tabela1[[#This Row],[Previsão no Parque ]],"MMMM") -> outubro | M5: =TEXT(Tabela1[[#This Row],[Previsão no Parque ]],"AAAA") -> 2026 | N5: Em rota | O5: 2 | P5: 46325
A6: =_xlfn.CONCAT(B6,D6) -> GP525859B856 | B6: GP525859 | C6: SCRAPER 105/117.2X8.1 M12T | D6: B856 | E6: VSMI | F6: 4 | G6: =IFERROR(VLOOKUP(A6,'Est. Parq.'!A:J,10,0),0) -> 2 | H6: =Tabela1[[#This Row],[Estoque Parque]]-Tabela1[[#This Row],[LRR]] -> -2 | I6: =SUMIF(SQVI!B:B,Base!A93,SQVI!V:V) -> 0 | J6: 46357 | K6: =UPPER(TEXT(Tabela1[[#This Row],[Previsão no Parque ]],"mmm/aaaa")) -> DEZ/2026 | L6: =TEXT(Tabela1[[#This Row],[Previsão no Parque ]],"MMMM") -> dezembro | M6: =TEXT(Tabela1[[#This Row],[Previsão no Parque ]],"AAAA") -> 2026 | N6: Pendente | Q6: 9 unids enviado para B857, proximo roteiro mais 3
A7: =_xlfn.CONCAT(B7,D7) -> GP525859B857 | B7: GP525859 | C7: SCRAPER 105/117.2X8.1 M12T | D7: B857 | E7: VSMII | F7: 8 | G7: =IFERROR(VLOOKUP(A7,'Est. Parq.'!A:J,10,0),0) -> 15 | H7: =Tabela1[[#This Row],[Estoque Parque]]-Tabela1[[#This Row],[LRR]] -> 7 | I7: =SUMIF(SQVI!B:B,Base!A94,SQVI!V:V) -> 60 | J7: 46296 | K7: =UPPER(TEXT(Tabela1[[#This Row],[Previsão no Parque ]],"mmm/aaaa")) -> OUT/2026 | L7: =TEXT(Tabela1[[#This Row],[Previsão no Parque ]],"MMMM") -> outubro | M7: =TEXT(Tabela1[[#This Row],[Previsão no Parque ]],"AAAA") -> 2026 | N7: Em rota | O7: 9 | P7: 46325
A8: =_xlfn.CONCAT(B8,D8) -> GP525859B867 | B8: GP525859 | C8: SCRAPER 105/117.2X8.1 M12T | D8: B867 | E8: VSMIII | F8: 2 | G8: =IFERROR(VLOOKUP(A8,'Est. Parq.'!A:J,10,0),0) -> 0 | H8: =Tabela1[[#This Row],[Estoque Parque]]-Tabela1[[#This Row],[LRR]] -> -2 | I8: =SUMIF(SQVI!B:B,Base!A95,SQVI!V:V) -> 42 | J8: 46357 | K8: =UPPER(TEXT(Tabela1[[#This Row],[Previsão no Parque ]],"mmm/aaaa")) -> DEZ/2026 | L8: =TEXT(Tabela1[[#This Row],[Previsão no Parque ]],"MMMM") -> dezembro | M8: =TEXT(Tabela1[[#This Row],[Previsão no Parque ]],"AAAA") -> 2026 | N8: Pendente
A9: =_xlfn.CONCAT(B9,D9) -> 109534B864 | B9: 109534 | C9: VALVULA RV8-10-C-0-50 | D9: B864 | E9: MARAL | G9: =IFERROR(VLOOKUP(A9,'Est. Parq.'!A:J,10,0),0) -> 5 | H9: =Tabela1[[#This Row],[Estoque Parque]]-Tabela1[[#This Row],[LRR]] -> 5 | I9: =SUMIF(SQVI!B:B,Base!A3,SQVI!V:V) -> 350 | J9: 46296 | K9: =UPPER(TEXT(Tabela1[[#This Row],[Previsão no Parque ]],"mmm/aaaa")) -> OUT/2026 | L9: =TEXT(Tabela1[[#This Row],[Previsão no Parque ]],"MMMM") -> outubro | M9: =TEXT(Tabela1[[#This Row],[Previsão no Parque ]],"AAAA") -> 2026 | N9: Em rota | O9: 2 | P9: 46325
A10: =_xlfn.CONCAT(B10,D10) -> 109534B865 | B10: 109534 | C10: VALVULA RV8-10-C-0-50 | D10: B865 | E10: TERRA SANTA | G10: =IFERROR(VLOOKUP(A10,'Est. Parq.'!A:J,10,0),0) -> 0 | H10: =Tabela1[[#This Row],[Estoque Parque]]-Tabela1[[#This Row],[LRR]] -> 0 | I10: =SUMIF(SQVI!B:B,Base!A2,SQVI!V:V) -> 0 | J10: 46266 | K10: =UPPER(TEXT(Tabela1[[#This Row],[Previsão no Parque ]],"mmm/aaaa")) -> SET/2026 | L10: =TEXT(Tabela1[[#This Row],[Previsão no Parque ]],"MMMM") -> setembro | M10: =TEXT(Tabela1[[#This Row],[Previsão no Parque ]],"AAAA") -> 2026 | N10: Entregue | O10: 2
A11: =_xlfn.CONCAT(B11,D11) -> 565784B864 | B11: 565784 | C11: REDUTORA PRV1-10-C-0-6 | D11: B864 | E11: MARAL | G11: =IFERROR(VLOOKUP(A11,'Est. Parq.'!A:J,10,0),0) -> 0 | H11: =Tabela1[[#This Row],[Estoque Parque]]-Tabela1[[#This Row],[LRR]] -> 0 | I11: =SUMIF(SQVI!B:B,Base!A5,SQVI!V:V) -> 6 | J11: 46296 | K11: =UPPER(TEXT(Tabela1[[#This Row],[Previsão no Parque ]],"mmm/aaaa")) -> OUT/2026 | L11: =TEXT(Tabela1[[#This Row],[Previsão no Parque ]],"MMMM") -> outubro | M11: =TEXT(Tabela1[[#This Row],[Previsão no Parque ]],"AAAA") -> 2026 | N11: Em rota | O11: 2 | P11: 46325
A12: =_xlfn.CONCAT(B12,D12) -> 565784B865 | B12: 565784 | C12: REDUTORA PRV1-10-C-0-6 | D12: B865 | E12: TERRA SANTA | F12: 1 | G12: =IFERROR(VLOOKUP(A12,'Est. Parq.'!A:J,10,0),0) -> 0 | H12: =Tabela1[[#This Row],[Estoque Parque]]-Tabela1[[#This Row],[LRR]] -> -1 | I12: =SUMIF(SQVI!B:B,Base!A4,SQVI!V:V) -> 0 | J12: 46266 | K12: =UPPER(TEXT(Tabela1[[#This Row],[Previsão no Parque ]],"mmm/aaaa")) -> SET/2026 | L12: =TEXT(Tabela1[[#This Row],[Previsão no Parque ]],"MMMM") -> setembro | M12: =TEXT(Tabela1[[#This Row],[Previsão no Parque ]],"AAAA") -> 2026 | N12: Entregue | O12: 2
A13: =_xlfn.CONCAT(B13,D13) -> AMB0155B864 | B13: AMB0155 | C13: VENTILADOR 230V 127W IP44 | D13: B864 | E13: MARAL | G13: =IFERROR(VLOOKUP(A13,'Est. Parq.'!A:J,10,0),0) -> 0 | H13: =Tabela1[[#This Row],[Estoque Parque]]-Tabela1[[#This Row],[LRR]] -> 0 | I13: =SUMIF(SQVI!B:B,Base!A7,SQVI!V:V) -> 30 | J13: 46419 | K13: =UPPER(TEXT(Tabela1[[#This Row],[Previsão no Parque ]],"mmm/aaaa")) -> FEV/2027 | L13: =TEXT(Tabela1[[#This Row],[Previsão no Parque ]],"MMMM") -> fevereiro | M13: =TEXT(Tabela1[[#This Row],[Previsão no Parque ]],"AAAA") -> 2027 | N13: Pendente
A14: =_xlfn.CONCAT(B14,D14) -> AMB0155B865 | B14: AMB0155 | C14: VENTILADOR 230V 127W IP44 | D14: B865 | E14: TERRA SANTA | G14: =IFERROR(VLOOKUP(A14,'Est. Parq.'!A:J,10,0),0) -> 0 | H14: =Tabela1[[#This Row],[Estoque Parque]]-Tabela1[[#This Row],[LRR]] -> 0 | I14: =SUMIF(SQVI!B:B,Base!A6,SQVI!V:V) -> 0 | J14: 46419 | K14: =UPPER(TEXT(Tabela1[[#This Row],[Previsão no Parque ]],"mmm/aaaa")) -> FEV/2027 | L14: =TEXT(Tabela1[[#This Row],[Previsão no Parque ]],"MMMM") -> fevereiro | M14: =TEXT(Tabela1[[#This Row],[Previsão no Parque ]],"AAAA") -> 2027 | N14: Pendente
A15: =_xlfn.CONCAT(B15,D15) -> GP004263B825 | B15: GP004263 | C15: OPTOCOUPLER RELAY OPT-24DC-24DC-2 | D15: B825 | E15: BLOCO NORTE SUL (BNS) | F15: 20 | G15: =IFERROR(VLOOKUP(A15,'Est. Parq.'!A:J,10,0),0) -> 0 | H15: =Tabela1[[#This Row],[Estoque Parque]]-Tabela1[[#This Row],[LRR]] -> -20 | I15: =SUMIF(SQVI!B:B,Base!A8,SQVI!V:V) -> 0 | J15: 46296 | K15: =UPPER(TEXT(Tabela1[[#This Row],[Previsão no Parque ]],"mmm/aaaa")) -> OUT/2026 | L15: =TEXT(Tabela1[[#This Row],[Previsão no Parque ]],"MMMM") -> outubro | M15: =TEXT(Tabela1[[#This Row],[Previsão no Parque ]],"AAAA") -> 2026 | N15: Em rota | O15: 13 | P15: 46325
A16: =_xlfn.CONCAT(B16,D16) -> GP004263B832 | B16: GP004263 | C16: OPTOCOUPLER RELAY OPT-24DC-24DC-2 | D16: B832 | E16: UNIÃO DOS VENTOS (UDV) | F16: 4 | G16: =IFERROR(VLOOKUP(A16,'Est. Parq.'!A:J,10,0),0) -> 0 | H16: =Tabela1[[#This Row],[Estoque Parque]]-Tabela1[[#This Row],[LRR]] -> -4 | I16: =SUMIF(SQVI!B:B,Base!A9,SQVI!V:V) -> 0 | J16: 46327 | K16: =UPPER(TEXT(Tabela1[[#This Row],[Previsão no Parque ]],"mmm/aaaa")) -> NOV/2026 | L16: =TEXT(Tabela1[[#This Row],[Previsão no Parque ]],"MMMM") -> novembro | M16: =TEXT(Tabela1[[#This Row],[Previsão no Parque ]],"AAAA") -> 2026 | N16: Pendente | Q16: Enviei no roteiro de outubro aos parques 64, 57,38, 56
A17: =_xlfn.CONCAT(B17,D17) -> GP004263B856 | B17: GP004263 | C17: OPTOCOUPLER RELAY OPT-24DC-24DC-2 | D17: B856 | E17: VSMI | F17: 2 | G17: =IFERROR(VLOOKUP(A17,'Est. Parq.'!A:J,10,0),0) -> 0 | H17: =Tabela1[[#This Row],[Estoque Parque]]-Tabela1[[#This Row],[LRR]] -> -2 | I17: =SUMIF(SQVI!B:B,Base!A10,SQVI!V:V) -> 0 | J17: 46296 | K17: =UPPER(TEXT(Tabela1[[#This Row],[Previsão no Parque ]],"mmm/aaaa")) -> OUT/2026 | L17: =TEXT(Tabela1[[#This Row],[Previsão no Parque ]],"MMMM") -> outubro | M17: =TEXT(Tabela1[[#This Row],[Previsão no Parque ]],"AAAA") -> 2026 | N17: Em rota | O17: 2 | P17: 46325
A18: =_xlfn.CONCAT(B18,D18) -> GP004263B857 | B18: GP004263 | C18: OPTOCOUPLER RELAY OPT-24DC-24DC-2 | D18: B857 | E18: VSMII | F18: 2 | G18: =IFERROR(VLOOKUP(A18,'Est. Parq.'!A:J,10,0),0) -> 0 | H18: =Tabela1[[#This Row],[Estoque Parque]]-Tabela1[[#This Row],[LRR]] -> -2 | I18: =SUMIF(SQVI!B:B,Base!A11,SQVI!V:V) -> 0 | J18: 46296 | K18: =UPPER(TEXT(Tabela1[[#This Row],[Previsão no Parque ]],"mmm/aaaa")) -> OUT/2026 | L18: =TEXT(Tabela1[[#This Row],[Previsão no Parque ]],"MMMM") -> outubro | M18: =TEXT(Tabela1[[#This Row],[Previsão no Parque ]],"AAAA") -> 2026 | N18: Em rota | O18: 5 | P18: 46325
A19: =_xlfn.CONCAT(B19,D19) -> GP004263B867 | B19: GP004263 | C19: OPTOCOUPLER RELAY OPT-24DC-24DC-2 | D19: B867 | E19: VSMIII | F19: 2 | G19: =IFERROR(VLOOKUP(A19,'Est. Parq.'!A:J,10,0),0) -> 0 | H19: =Tabela1[[#This Row],[Estoque Parque]]-Tabela1[[#This Row],[LRR]] -> -2 | I19: =SUMIF(SQVI!B:B,Base!A12,SQVI!V:V) -> 0 | J19: 46296 | K19: =UPPER(TEXT(Tabela1[[#This Row],[Previsão no Parque ]],"mmm/aaaa")) -> OUT/2026 | L19: =TEXT(Tabela1[[#This Row],[Previsão no Parque ]],"MMMM") -> outubro | M19: =TEXT(Tabela1[[#This Row],[Previsão no Parque ]],"AAAA") -> 2026 | N19: Em rota | O19: 18 | P19: 46325
A20: =_xlfn.CONCAT(B20,D20) -> GP004892B825 | B20: GP004892 | C20: ENTRADAS DIGITAIS | D20: B825 | E20: BLOCO NORTE SUL (BNS) | F20: 1 | G20: =IFERROR(VLOOKUP(A20,'Est. Parq.'!A:J,10,0),0) -> 0 | H20: =Tabela1[[#This Row],[Estoque Parque]]-Tabela1[[#This Row],[LRR]] -> -1 | I20: =SUMIF(SQVI!B:B,Base!A13,SQVI!V:V) -> 0 | J20: 46388 | K20: =UPPER(TEXT(Tabela1[[#This Row],[Previsão no Parque ]],"mmm/aaaa")) -> JAN/2027 | L20: =TEXT(Tabela1[[#This Row],[Previsão no Parque ]],"MMMM") -> janeiro | M20: =TEXT(Tabela1[[#This Row],[Previsão no Parque ]],"AAAA") -> 2027 | N20: Sem necessidade parque
A21: =_xlfn.CONCAT(B21,D21) -> GP004897B865 | B21: GP004897 | C21: ENTRADAS ANALOGICAS | D21: B865 | E21: TERRA SANTA | F21: 10 | G21: =IFERROR(VLOOKUP(A21,'Est. Parq.'!A:J,10,0),0) -> 0 | H21: =Tabela1[[#This Row],[Estoque Parque]]-Tabela1[[#This Row],[LRR]] -> -10 | I21: =SUMIF(SQVI!B:B,Base!A14,SQVI!V:V) -> 0 | J21: 46327 | K21: =UPPER(TEXT(Tabela1[[#This Row],[Previsão no Parque ]],"mmm/aaaa")) -> NOV/2026 | L21: =TEXT(Tabela1[[#This Row],[Previsão no Parque ]],"MMMM") -> novembro | M21: =TEXT(Tabela1[[#This Row],[Previsão no Parque ]],"AAAA") -> 2026 | N21: Entregue parcial | O21: -2 | P21: 46221 | Q21: Aguardando entrada do material
A22: =_xlfn.CONCAT(B22,D22) -> GP004897B864 | B22: GP004897 | C22: ENTRADAS ANALOGICAS | D22: B864 | E22: MARAL | F22: 5 | G22: =IFERROR(VLOOKUP(A22,'Est. Parq.'!A:J,10,0),0) -> 0 | H22: =Tabela1[[#This Row],[Estoque Parque]]-Tabela1[[#This Row],[LRR]] -> -5 | I22: =SUMIF(SQVI!B:B,Base!A15,SQVI!V:V) -> 30 | J22: 46327 | K22: =UPPER(TEXT(Tabela1[[#This Row],[Previsão no Parque ]],"mmm/aaaa")) -> NOV/2026 | L22: =TEXT(Tabela1[[#This Row],[Previsão no Parque ]],"MMMM") -> novembro | M22: =TEXT(Tabela1[[#This Row],[Previsão no Parque ]],"AAAA") -> 2026 | N22: Pendente | Q22: Aguardando entrada do material
A23: =_xlfn.CONCAT(B23,D23) -> GP004975B825 | B23: GP004975 | C23: PLC CONTROLADOR DE CAMPO | D23: B825 | E23: BLOCO NORTE SUL (BNS) | F23: 3 | G23: =IFERROR(VLOOKUP(A23,'Est. Parq.'!A:J,10,0),0) -> 0 | H23: =Tabela1[[#This Row],[Estoque Parque]]-Tabela1[[#This Row],[LRR]] -> -3 | I23: =SUMIF(SQVI!B:B,Base!A16,SQVI!V:V) -> 0 | J23: 46266 | K23: =UPPER(TEXT(Tabela1[[#This Row],[Previsão no Parque ]],"mmm/aaaa")) -> SET/2026 | L23: =TEXT(Tabela1[[#This Row],[Previsão no Parque ]],"MMMM") -> setembro | M23: =TEXT(Tabela1[[#This Row],[Previsão no Parque ]],"AAAA") -> 2026 | N23: Entregue | O23: -1 | P23: 46255
A24: =_xlfn.CONCAT(B24,D24) -> GP008618B856 | B24: GP008618 | C24: On delay time RockWell 700-HT3 | D24: B856 | E24: VSMI | F24: 2 | G24: =IFERROR(VLOOKUP(A24,'Est. Parq.'!A:J,10,0),0) -> 2 | H24: =Tabela1[[#This Row],[Estoque Parque]]-Tabela1[[#This Row],[LRR]] -> 0 | I24: =SUMIF(SQVI!B:B,Base!A17,SQVI!V:V) -> 4 | J24: 46327 | K24: =UPPER(TEXT(Tabela1[[#This Row],[Previsão no Parque ]],"mmm/aaaa")) -> NOV/2026 | L24: =TEXT(Tabela1[[#This Row],[Previsão no Parque ]],"MMMM") -> novembro | M24: =TEXT(Tabela1[[#This Row],[Previsão no Parque ]],"AAAA") -> 2026 | N24: Pendente | Q24: Aguardando entrada do material
A25: =_xlfn.CONCAT(B25,D25) -> GP013211B832 | B25: GP013211 | C25: GENERICO OLEOS DA UNIDADE HIDRAULICA | D25: B832 | E25: UNIÃO DOS VENTOS (UDV) | G25: =IFERROR(VLOOKUP(A25,'Est. Parq.'!A:J,10,0),0) -> 3 | H25: =Tabela1[[#This Row],[Estoque Parque]]-Tabela1[[#This Row],[LRR]] -> 3 | I25: =SUMIF(SQVI!B:B,Base!A18,SQVI!V:V) -> 0 | J25: 46266 | K25: =UPPER(TEXT(Tabela1[[#This Row],[Previsão no Parque ]],"mmm/aaaa")) -> SET/2026 | L25: =TEXT(Tabela1[[#This Row],[Previsão no Parque ]],"MMMM") -> setembro | M25: =TEXT(Tabela1[[#This Row],[Previsão no Parque ]],"AAAA") -> 2026 | N25: Entregue
A26: =_xlfn.CONCAT(B26,D26) -> GP019518B856 | B26: GP019518 | C26: SWITCH ETHERNET MOXA EDS-308-MM-ST | D26: B856 | E26: VSMI | G26: =IFERROR(VLOOKUP(A26,'Est. Parq.'!A:J,10,0),0) -> 0 | H26: =Tabela1[[#This Row],[Estoque Parque]]-Tabela1[[#This Row],[LRR]] -> 0 | I26: =SUMIF(SQVI!B:B,Base!A19,SQVI!V:V) -> 0 | J26: 46388 | K26: =UPPER(TEXT(Tabela1[[#This Row],[Previsão no Parque ]],"mmm/aaaa")) -> JAN/2027 | L26: =TEXT(Tabela1[[#This Row],[Previsão no Parque ]],"MMMM") -> janeiro | M26: =TEXT(Tabela1[[#This Row],[Previsão no Parque ]],"AAAA") -> 2027 | N26: Entregue parcial | O26: -2 | P26: 46253
A27: =_xlfn.CONCAT(B27,D27) -> GP023882B825 | B27: GP023882 | C27: DIODO PADRAO 540A 2700V XX | D27: B825 | E27: BLOCO NORTE SUL (BNS) | F27: 2 | G27: =IFERROR(VLOOKUP(A27,'Est. Parq.'!A:J,10,0),0) -> 0 | H27: =Tabela1[[#This Row],[Estoque Parque]]-Tabela1[[#This Row],[LRR]] -> -2 | I27: =SUMIF(SQVI!B:B,Base!A20,SQVI!V:V) -> 0 | J27: 46419 | K27: =UPPER(TEXT(Tabela1[[#This Row],[Previsão no Parque ]],"mmm/aaaa")) -> FEV/2027 | L27: =TEXT(Tabela1[[#This Row],[Previsão no Parque ]],"MMMM") -> fevereiro | M27: =TEXT(Tabela1[[#This Row],[Previsão no Parque ]],"AAAA") -> 2027 | N27: Criar RC
A28: =_xlfn.CONCAT(B28,D28) -> GP069610B864 | B28: GP069610 | C28: LEVEL SWITCH HINE LM1FA500NASP ALARM | D28: B864 | E28: MARAL | F28: 2 | G28: =IFERROR(VLOOKUP(A28,'Est. Parq.'!A:J,10,0),0) -> 2 | H28: =Tabela1[[#This Row],[Estoque Parque]]-Tabela1[[#This Row],[LRR]] -> 0 | I28: =SUMIF(SQVI!B:B,Base!A21,SQVI!V:V) -> 0 | J28: 46296 | K28: =UPPER(TEXT(Tabela1[[#This Row],[Previsão no Parque ]],"mmm/aaaa")) -> OUT/2026 | L28: =TEXT(Tabela1[[#This Row],[Previsão no Parque ]],"MMMM") -> outubro | M28: =TEXT(Tabela1[[#This Row],[Previsão no Parque ]],"AAAA") -> 2026 | N28: Em rota | O28: 2 | P28: 46325
A29: =_xlfn.CONCAT(B29,D29) -> GP069610 B865 | B29: GP069610 | C29: LEVEL SWITCH HINE LM1FA500NASP ALARM | D29: B865 | E29: TERRA SANTA | G29: =IFERROR(VLOOKUP(A29,'Est. Parq.'!A:J,10,0),0) -> 0 | H29: =Tabela1[[#This Row],[Estoque Parque]]-Tabela1[[#This Row],[LRR]] -> 0 | I29: =SUMIF(SQVI!B:B,Base!A22,SQVI!V:V) -> 0 | J29: 46266 | K29: =UPPER(TEXT(Tabela1[[#This Row],[Previsão no Parque ]],"mmm/aaaa")) -> SET/2026 | L29: =TEXT(Tabela1[[#This Row],[Previsão no Parque ]],"MMMM") -> setembro | M29: =TEXT(Tabela1[[#This Row],[Previsão no Parque ]],"AAAA") -> 2026 | N29: Criar RC | Q29: Embarcado no roteiro para B864 2 unids
A30: =_xlfn.CONCAT(B30,D30) -> GP078780B838 | B30: GP078780 | C30: SMP12C | D30: B838 | E30: VACI | F30: 1 | G30: =IFERROR(VLOOKUP(A30,'Est. Parq.'!A:J,10,0),0) -> 0 | H30: =Tabela1[[#This Row],[Estoque Parque]]-Tabela1[[#This Row],[LRR]] -> -1 | I30: =SUMIF(SQVI!B:B,Base!A23,SQVI!V:V) -> 2 | J30: 46388 | K30: =UPPER(TEXT(Tabela1[[#This Row],[Previsão no Parque ]],"mmm/aaaa")) -> JAN/2027 | L30: =TEXT(Tabela1[[#This Row],[Previsão no Parque ]],"MMMM") -> janeiro | M30: =TEXT(Tabela1[[#This Row],[Previsão no Parque ]],"AAAA") -> 2027 | N30: Pendente
A31: =_xlfn.CONCAT(B31,D31) -> GP082783B865 | B31: GP082783 | C31: IB IL TEMP 4/8 RTD/EF-PAC | D31: B865 | E31: TERRA SANTA | F31: 10 | G31: =IFERROR(VLOOKUP(A31,'Est. Parq.'!A:J,10,0),0) -> 5 | H31: =Tabela1[[#This Row],[Estoque Parque]]-Tabela1[[#This Row],[LRR]] -> -5 | I31: =SUMIF(SQVI!B:B,Base!A24,SQVI!V:V) -> 0 | J31: 46327 | K31: =UPPER(TEXT(Tabela1[[#This Row],[Previsão no Parque ]],"mmm/aaaa")) -> NOV/2026 | L31: =TEXT(Tabela1[[#This Row],[Previsão no Parque ]],"MMMM") -> novembro | M31: =TEXT(Tabela1[[#This Row],[Previsão no Parque ]],"AAAA") -> 2026 | N31: Pendente | Q31: Embarcado no roteiro para B857 1 unid
A32: =_xlfn.CONCAT(B32,D32) -> GP082783B864 | B32: GP082783 | C32: IB IL TEMP 4/8 RTD/EF-PAC | D32: B864 | E32: MARAL | F32: 5 | G32: =IFERROR(VLOOKUP(A32,'Est. Parq.'!A:J,10,0),0) -> 19 | H32: =Tabela1[[#This Row],[Estoque Parque]]-Tabela1[[#This Row],[LRR]] -> 14 | I32: =SUMIF(SQVI!B:B,Base!A25,SQVI!V:V) -> 0 | J32: 46296 | K32: =UPPER(TEXT(Tabela1[[#This Row],[Previsão no Parque ]],"mmm/aaaa")) -> OUT/2026 | L32: =TEXT(Tabela1[[#This Row],[Previsão no Parque ]],"MMMM") -> outubro | M32: =TEXT(Tabela1[[#This Row],[Previsão no Parque ]],"AAAA") -> 2026 | N32: Em rota | O32: 2 | P32: 46325
A33: =_xlfn.CONCAT(B33,D33) -> GP091014B825 | B33: GP091014 | C33: RESISTENCIA DE POTENCIA 33R 600W 10% | D33: B825 | E33: BLOCO NORTE SUL (BNS) | F33: 1 | G33: =IFERROR(VLOOKUP(A33,'Est. Parq.'!A:J,10,0),0) -> 5 | H33: =Tabela1[[#This Row],[Estoque Parque]]-Tabela1[[#This Row],[LRR]] -> 4 | I33: =SUMIF(SQVI!B:B,Base!A26,SQVI!V:V) -> 0 | J33: 46266 | K33: =UPPER(TEXT(Tabela1[[#This Row],[Previsão no Parque ]],"mmm/aaaa")) -> SET/2026 | L33: =TEXT(Tabela1[[#This Row],[Previsão no Parque ]],"MMMM") -> setembro | M33: =TEXT(Tabela1[[#This Row],[Previsão no Parque ]],"AAAA") -> 2026 | N33: Entregue | O33: -5 | P33: 46247
A34: =_xlfn.CONCAT(B34,D34) -> GP091145B832 | B34: GP091145 | C34: CARTÃO DUPLO DE DRIVERS | D34: B832 | E34: UNIÃO DOS VENTOS (UDV) | G34: =IFERROR(VLOOKUP(A34,'Est. Parq.'!A:J,10,0),0) -> 0 | H34: =Tabela1[[#This Row],[Estoque Parque]]-Tabela1[[#This Row],[LRR]] -> 0 | I34: =SUMIF(SQVI!B:B,Base!A27,SQVI!V:V) -> 0 | J34: 46327 | K34: =UPPER(TEXT(Tabela1[[#This Row],[Previsão no Parque ]],"mmm/aaaa")) -> NOV/2026 | L34: =TEXT(Tabela1[[#This Row],[Previsão no Parque ]],"MMMM") -> novembro | M34: =TEXT(Tabela1[[#This Row],[Previsão no Parque ]],"AAAA") -> 2026 | N34: Pendente
A35: =_xlfn.CONCAT(B35,D35) -> GP124403B856 | B35: GP124403 | C35: AMB_EBM_K2E225RA9209 | D35: B856 | E35: VSMI | F35: 2 | G35: =IFERROR(VLOOKUP(A35,'Est. Parq.'!A:J,10,0),0) -> 12 | H35: =Tabela1[[#This Row],[Estoque Parque]]-Tabela1[[#This Row],[LRR]] -> 10 | I35: =SUMIF(SQVI!B:B,Base!A28,SQVI!V:V) -> 0 | J35: 46266 | K35: =UPPER(TEXT(Tabela1[[#This Row],[Previsão no Parque ]],"mmm/aaaa")) -> SET/2026 | L35: =TEXT(Tabela1[[#This Row],[Previsão no Parque ]],"MMMM") -> setembro | M35: =TEXT(Tabela1[[#This Row],[Previsão no Parque ]],"AAAA") -> 2026 | N35: Entregue | O35: -10 | P35: 46253
A36: =_xlfn.CONCAT(B36,D36) -> GP124403B857 | B36: GP124403 | C36: CENTRIFUGAL FAN 230V\1260m3\h UL-LOW NOI | D36: B857 | E36: VSMII | G36: =IFERROR(VLOOKUP(A36,'Est. Parq.'!A:J,10,0),0) -> 2 | H36: =Tabela1[[#This Row],[Estoque Parque]]-Tabela1[[#This Row],[LRR]] -> 2 | I36: =SUMIF(SQVI!B:B,Base!A29,SQVI!V:V) -> 0 | J36: 46235 | K36: =UPPER(TEXT(Tabela1[[#This Row],[Previsão no Parque ]],"mmm/aaaa")) -> AGO/2026 | L36: =TEXT(Tabela1[[#This Row],[Previsão no Parque ]],"MMMM") -> agosto | M36: =TEXT(Tabela1[[#This Row],[Previsão no Parque ]],"AAAA") -> 2026 | N36: Sem necessidade parque
A37: =_xlfn.CONCAT(B37,D37) -> GP124403B867 | B37: GP124403 | C37: CENTRIFUGAL FAN 230V\1260m3\h UL-LOW NOI | D37: B867 | E37: VSMIII | F37: 2 | G37: =IFERROR(VLOOKUP(A37,'Est. Parq.'!A:J,10,0),0) -> 6 | H37: =Tabela1[[#This Row],[Estoque Parque]]-Tabela1[[#This Row],[LRR]] -> 4 | I37: =SUMIF(SQVI!B:B,Base!A30,SQVI!V:V) -> 3 | J37: 46235 | K37: =UPPER(TEXT(Tabela1[[#This Row],[Previsão no Parque ]],"mmm/aaaa")) -> AGO/2026 | L37: =TEXT(Tabela1[[#This Row],[Previsão no Parque ]],"MMMM") -> agosto | M37: =TEXT(Tabela1[[#This Row],[Previsão no Parque ]],"AAAA") -> 2026 | N37: Sem necessidade parque | O37: -4 | P37: 46195
A38: =_xlfn.CONCAT(B38,D38) -> GP127960B832 | B38: GP127960 | C38: GENERIC G9X ELECTRIC ROTATING JOINT STD | D38: B832 | E38: UNIÃO DOS VENTOS (UDV) | F38: 4 | G38: =IFERROR(VLOOKUP(A38,'Est. Parq.'!A:J,10,0),0) -> 6 | H38: =Tabela1[[#This Row],[Estoque Parque]]-Tabela1[[#This Row],[LRR]] -> 2 | I38: =SUMIF(SQVI!B:B,Base!A31,SQVI!V:V) -> 0 | J38: 46266 | K38: =UPPER(TEXT(Tabela1[[#This Row],[Previsão no Parque ]],"mmm/aaaa")) -> SET/2026 | L38: =TEXT(Tabela1[[#This Row],[Previsão no Parque ]],"MMMM") -> setembro | M38: =TEXT(Tabela1[[#This Row],[Previsão no Parque ]],"AAAA") -> 2026 | N38: Entregue | O38: -2 | P38: 46248
A39: =_xlfn.CONCAT(B39,D39) -> GP127960B838 | B39: GP127960 | C39: GENERIC G9X ELECTRIC ROTATING JOINT STD | D39: B838 | E39: VACI | F39: 2 | G39: =IFERROR(VLOOKUP(A39,'Est. Parq.'!A:J,10,0),0) -> 1 | H39: =Tabela1[[#This Row],[Estoque Parque]]-Tabela1[[#This Row],[LRR]] -> -1 | I39: =SUMIF(SQVI!B:B,Base!A32,SQVI!V:V) -> 5 | J39: 46296 | K39: =UPPER(TEXT(Tabela1[[#This Row],[Previsão no Parque ]],"mmm/aaaa")) -> OUT/2026 | L39: =TEXT(Tabela1[[#This Row],[Previsão no Parque ]],"MMMM") -> outubro | M39: =TEXT(Tabela1[[#This Row],[Previsão no Parque ]],"AAAA") -> 2026 | N39: Em rota | O39: 2 | P39: 46325
A40: =_xlfn.CONCAT(B40,D40) -> GP127960B856 | B40: GP127960 | C40: GENERIC G9X ELECTRIC ROTATING JOINT STD | D40: B856 | E40: VSMI | F40: 2 | G40: =IFERROR(VLOOKUP(A40,'Est. Parq.'!A:J,10,0),0) -> 2 | H40: =Tabela1[[#This Row],[Estoque Parque]]-Tabela1[[#This Row],[LRR]] -> 0 | I40: =SUMIF(SQVI!B:B,Base!A33,SQVI!V:V) -> 0 | J40: 46388 | K40: =UPPER(TEXT(Tabela1[[#This Row],[Previsão no Parque ]],"mmm/aaaa")) -> JAN/2027 | L40: =TEXT(Tabela1[[#This Row],[Previsão no Parque ]],"MMMM") -> janeiro | M40: =TEXT(Tabela1[[#This Row],[Previsão no Parque ]],"AAAA") -> 2027 | N40: Criar RC
...

Sheet Grafico

Sheet SQVI
A1: conc | B1: conc | C1: ReqC | D1: Item | E1: Sua ref. | F1: Requisitante | G1: Criado por | H1: Tipo | I1: Dt.criação | J1: Doc.compra | K1: Item | L1: Fornecedor | M1: OrgC | N1: CFor | O1: DepSaí | P1: Data mod. | Q1: E | R1: Cen. | S1: Dep. | T1: Material | U1: TxtBreve | V1: Qtd.pedido | W1: UMP | X1: UMP | Y1: Preço líq. | Z1: Moeda | AA1: CI | AB1: Tp.aval. | AC1: CtgAvl | AD1: Nº acomp. | AE1: Cód.NCM | AF1: U | AG1: O | AH1: PriorNeces. | AI1: PlnIt | AJ1: Div. | AK1: Qtd.confir. | AL1: UMP | AM1: Dt.remessa | AN1: DataConf. | AO1: Data prep. | AP1: Dt.carreg. | AQ1: OrgTransp. | AR1: SaídaMerc | AS1: Data fim da EM | AT1: Esq. | AU1: Perfil | AV1: C | AW1: CRC | AX1: PEP | AY1: TEM | AZ1: E | BA1: Qtd.saída | BB1: UMP | BC1: Fornecimento | BD1: Qtd.remessa | BE1: Data prep.material | BF1: Confirmação picking | BG1: Sugestão BR1 | BH1: Criado por GEP | BI1: Header GEP
A2: =I2&J2 -> 461664501742979 | B2: =_xlfn.CONCAT(T2,R2) -> GP486978-004B832 | D2: 0 | E2: 42489930 | F2: SPOTPrev | G2: DMC_Z004C56J | H2: NB | I2: 46166 | J2: 4501742979 | K2: 30 | L2: X002178424 | M2: 749A | P2: 46267 | R2: B832 | S2: SUV1 | T2: GP486978-004 | U2: SHELL TELLUS S2VX32 FINE HYDR OIL 208,2L | V2: 416.4 | W2: L | X2: L | Y2: 3700.28 | Z2: ZBR | AA2: TD | AE2: 27101932 | AF2: 2 | AG2: 2 | AH2: 0 | AJ2: 1 | AK2: 0 | AL2: L | AM2: 46199 | AT2: ZR0000 | AV2: R | AX2: 33 | AY2: 2 | BA2: 0 | BB2: L | BC2: #N/A | BD2: #N/A | BE2: #N/A | BF2: #N/A | BG2: LRR | BH2: EOLIVEIRA | BI2: LRR
A3: =I3&J3 -> 461914501750844 | B3: =_xlfn.CONCAT(T3,R3) -> A9B00019165B832 | D3: 0 | E3: 42456224 | F3: Planf. compr | G3: DMC_Z004C56J | H3: NB | I3: 46191 | J3: 4501750844 | K3: 10 | L3: X002178424 | M3: 749A | P3: 46191 | R3: B832 | S3: SUV1 | T3: A9B00019165 | U3: GREASE SHELL RHODINA, 5 KG, BBZ | V3: 10 | W3: KG | X3: KG | Y3: 6806.75 | Z3: ZBR | AA3: DP | AD3: CONSUM | AE3: 34031900 | AF3: 2 | AG3: 2 | AH3: 0 | AJ3: 1 | AK3: 0 | AL3: KG | AM3: 46245 | AT3: ZR0000 | AV3: R | AX3: 54 | AY3: 2 | BA3: 0 | BB3: KG | BC3: #N/A | BD3: #N/A | BE3: #N/A | BF3: #N/A | BG3: LRR | BH3: 1069141 | BI3: LRR
A4: =I4&J4 -> 461914501750922 | B4: =_xlfn.CONCAT(T4,R4) -> GP485052-003B825 | D4: 0 | E4: 42470255 | F4: corretiva | G4: DMC_Z004C56J | H4: NB | I4: 46191 | J4: 4501750922 | K4: 10 | L4: X002178424 | M4: 749A | P4: 46267 | R4: B825 | S4: SBN1 | T4: GP485052-003 | U4: SHELL OMALA S3 WIND MINERAL 20L (UMB L) | V4: 300 | W4: L | X4: L | Y4: 38860.97 | Z4: ZBR | AA4: TD | AE4: 27101932 | AF4: 2 | AG4: 2 | AH4: 0 | AJ4: 1 | AK4: 0 | AL4: L | AM4: 46224 | AT4: ZR0000 | AV4: R | AX4: 33 | AY4: 2 | BA4: 0 | BB4: L | BC4: #N/A | BD4: #N/A | BE4: #N/A | BF4: #N/A | BG4: CORRETIVA | BH4: EOLIVEIRA | BI4: SPOT
A5: =I5&J5 -> 461914501751037 | B5: =_xlfn.CONCAT(T5,R5) -> GP485052-003B825 | D5: 0 | E5: 42483197 | F5: Planf. compr | G5: DMC_Z004C56J | H5: NB | I5: 46191 | J5: 4501751037 | K5: 20 | L5: X002178424 | M5: 749A | P5: 46267 | R5: B825 | S5: SBN1 | T5: GP485052-003 | U5: SHELL OMALA S3 WIND MINERAL 20L (UMB L) | V5: 100 | W5: L | X5: L | Y5: 70196.97 | Z5: ZBR | AA5: M4 | AE5: 27101932 | AF5: 2 | AG5: 2 | AH5: 0 | AJ5: 1 | AK5: 0 | AL5: L | AM5: 46224 | AT5: ZR0000 | AV5: R | AX5: 33 | AY5: 2 | BA5: 0 | BB5: L | BC5: #N/A | BD5: #N/A | BE5: #N/A | BF5: #N/A | BG5: LRR | BH5: EOLIVEIRA | BI5: LRR
A6: =I6&J6 -> 461914501751067 | B6: =_xlfn.CONCAT(T6,R6) -> GP485052-003B825 | D6: 0 | E6: 42486040 | F6: Planf. compr | G6: DMC_Z004C56J | H6: NB | I6: 46191 | J6: 4501751067 | K6: 10 | L6: X002178424 | M6: 749A | P6: 46191 | R6: B825 | S6: SBN1 | T6: GP485052-003 | U6: SHELL OMALA S3 WIND MINERAL 20L (UMB L) | V6: 200 | W6: L | X6: L | Y6: 31413.38 | Z6: ZBR | AA6: DS | AE6: 27101932 | AF6: 2 | AG6: 2 | AH6: 0 | AJ6: 1 | AK6: 0 | AL6: L | AM6: 46224 | AT6: ZR0000 | AV6: R | AX6: 33 | AY6: 2 | BA6: 0 | BB6: L | BC6: #N/A | BD6: #N/A | BE6: #N/A | BF6: #N/A | BG6: LRR | BH6: EOLIVEIRA | BI6: LRR
A7: =I7&J7 -> 461914501751068 | B7: =_xlfn.CONCAT(T7,R7) -> GP485051-001B857 | D7: 0 | E7: 42486051 | F7: Planf. compr | G7: DMC_Z004C56J | H7: NB | I7: 46191 | J7: 4501751068 | K7: 10 | L7: X002178424 | M7: 749A | P7: 46267 | R7: B857 | S7: SVS2 | T7: GP485051-001 | U7: SHELL OMALA S5 WIND SYNTHETIC_ 20L | V7: 80 | W7: L | X7: L | Y7: 888.87 | Z7: ZBR | AA7: M4 | AE7: 34031900 | AF7: 2 | AG7: 2 | AH7: 0 | AJ7: 1 | AK7: 0 | AL7: L | AM7: 46251 | AT7: ZR0000 | AV7: R | AX7: 60 | AY7: 2 | BA7: 0 | BB7: L | BC7: #N/A | BD7: #N/A | BE7: #N/A | BF7: #N/A | BG7: LRR | BH7: EOLIVEIRA | BI7: LRR
A8: =I8&J8 -> 461914501751131 | B8: =_xlfn.CONCAT(T8,R8) -> GP486978-004B825 | D8: 0 | E8: 42489911 | F8: SPOTCor | G8: DMC_Z004C56J | H8: NB | I8: 46191 | J8: 4501751131 | K8: 10 | L8: X002178424 | M8: 749A | P8: 46204 | R8: B825 | S8: SBN1 | T8: GP486978-004 | U8: SHELL TELLUS S2VX32 FINE HYDR OIL 208,2L | V8: 1041 | W8: L | X8: L | Y8: 3696.72 | Z8: ZBR | AA8: TD | AE8: 27101932 | AF8: 2 | AG8: 0 | AH8: 0 | AJ8: 1 | AK8: 0 | AL8: L | AM8: 46224 | AT8: ZR0000 | AV8: R | AX8: 33 | AY8: 2 | BA8: 0 | BB8: L | BC8: #N/A | BD8: #N/A | BE8: #N/A | BF8: #N/A | BG8: CORRETIVA | BH8: EOLIVEIRA | BI8: corretivo e tratativas de ats.
A9: =I9&J9 -> 461914501751220 | B9: =_xlfn.CONCAT(T9,R9) -> GP013211B857 | D9: 0 | E9: 42493509 | F9: SPOTCor | G9: DMC_Z004C56J | H9: NB | I9: 46191 | J9: 4501751220 | K9: 10 | L9: X002178424 | M9: 749A | P9: 46267 | R9: B857 | S9: SVS2 | T9: GP013211 | U9: GENERICO OLEOS DA UNIDADE HIDRAULICA | V9: 3 | W9: REC | X9: REC | Y9: 3564.66 | Z9: ZBR | AA9: DP | AE9: 27101932 | AF9: 2 | AG9: 5 | AH9: 0 | AJ9: 1 | AK9: 0 | AL9: REC | AM9: 46286 | AT9: ZR0000 | AV9: R | AX9: 21 | AY9: 2 | BA9: 0 | BB9: REC | BC9: #N/A | BD9: #N/A | BE9: #N/A | BF9: #N/A | BG9: CORRETIVA | BH9: EOLIVEIRA | BI9: SUPRIR NECESSIDADE DO TELLUS FINE
A10: =I10&J10 -> 462034501752680 | B10: =_xlfn.CONCAT(T10,R10) -> GP486978-004B825 | C10: 1079449016 | D10: 10 | F10: Z005396H | G10: Z0047JVE | H10: NB | I10: 46203 | J10: 4501752680 | K10: 20 | L10: X002178424 | M10: 749A | P10: 46205 | Q10: L | R10: B825 | S10: SBN1 | T10: GP486978-004 | U10: SHELL TELLUS S2VX32 FINE HYDR OIL 208,2L | V10: 10 | W10: TAM | X10: TAM | Y10: 3551.02 | Z10: ZBR | AA10: TD | AE10: 27101932 | AF10: 2 | AG10: 2 | AH10: 0 | AJ10: 1 | AK10: 0 | AL10: TAM | AM10: 46237 | AT10: ZR0000 | AV10: R | AX10: 60 | AY10: 2 | BA10: 0 | BB10: TAM | BC10: #N/A | BD10: #N/A | BE10: #N/A | BF10: #N/A | BG10: CORRETIVA | BH10: #N/A | BI10: #N/A
A11: =I11&J11 -> 462384501758104 | B11: =_xlfn.CONCAT(T11,R11) -> GP486978-004B833 | C11: 1079768759 | D11: 10 | F11: Z005396H | G11: Z005AMNR | H11: NB | I11: 46238 | J11: 4501758104 | K11: 10 | L11: X002178424 | M11: 749A | P11: 46238 | R11: B833 | S11: SUV2 | T11: GP486978-004 | U11: SHELL TELLUS S2VX32 FINE HYDR OIL 208,2L | V11: 388.2 | W11: L | X11: L | Y11: 3551.02 | Z11: ZBR | AA11: TD | AE11: 27101932 | AF11: 2 | AG11: 2 | AH11: 0 | AJ11: 1 | AK11: 0 | AL11: L | AM11: 46314 | AT11: ZR0000 | AV11: R | AX11: 60 | AY11: 2 | BA11: 0 | BB11: L | BC11: #N/A | BD11: #N/A | BE11: #N/A | BF11: #N/A | BG11: #N/A | BH11: #N/A | BI11: #N/A
A12: =I12&J12 -> 462384501758114 | B12: =_xlfn.CONCAT(T12,R12) -> GP486978-004B857 | C12: 1080077829 | D12: 10 | F12: Planf. compr | G12: Z0047AAZ | H12: NB | I12: 46238 | J12: 4501758114 | K12: 10 | L12: X002178424 | M12: 749A | P12: 46253 | R12: B857 | S12: SVS2 | T12: GP486978-004 | U12: SHELL TELLUS S2VX32 FINE HYDR OIL 208,2L | V12: 624.6 | W12: L | X12: L | Y12: 3700.28 | Z12: ZBR | AA12: TD | AE12: 27101932 | AF12: 2 | AG12: 2 | AH12: 0 | AJ12: 1 | AK12: 0 | AL12: L | AM12: 46255 | AT12: ZR0000 | AV12: R | AX12: 60 | AY12: 2 | BA12: 0 | BB12: L | BC12: #N/A | BD12: #N/A | BE12: #N/A | BF12: #N/A | BG12: #N/A | BH12: #N/A | BI12: #N/A
A13: =I13&J13 -> 462574501760680 | B13: =_xlfn.CONCAT(T13,R13) -> GP486978-004B865 | C13: 1079768760 | D13: 10 | F13: Z005396H | G13: Z00488YE | H13: NB | I13: 46257 | J13: 4501760680 | K13: 10 | L13: X002178424 | M13: 749A | P13: 46275 | R13: B865 | S13: STS1 | T13: GP486978-004 | U13: SHELL TELLUS S2VX32 FINE HYDR OIL 208,2L | V13: 416.4 | W13: L | X13: L | Y13: 4055.84 | Z13: ZBR | AA13: TD | AE13: 27101932 | AF13: 2 | AG13: 2 | AH13: 0 | AJ13: 1 | AK13: 0 | AL13: L | AM13: 46314 | AT13: ZR0000 | AV13: R | AX13: 60 | AY13: 2 | BA13: 0 | BB13: L | BC13: #N/A | BD13: #N/A | BE13: #N/A | BF13: #N/A | BG13: #N/A | BH13: #N/A | BI13: #N/A
A14: =I14&J14 -> 462644501761685 | B14: =_xlfn.CONCAT(T14,R14) -> GP486978-004B825 | C14: 1080420691 | D14: 10 | F14: Z00414MR | G14: Z00488YE | H14: NB | I14: 46264 | J14: 4501761685 | K14: 10 | L14: X002178424 | M14: 749A | P14: 46264 | R14: B825 | S14: SBN1 | T14: GP486978-004 | U14: SHELL TELLUS S2VX32 FINE HYDR OIL 208,2L | V14: 2082 | W14: L | X14: L | Y14: 3903.01 | Z14: ZBR | AA14: TD | AE14: 27101932 | AF14: 2 | AG14: 2 | AH14: 0 | AJ14: 1 | AK14: 0 | AL14: L | AM14: 46295 | AT14: ZR0000 | AV14: R | AX14: 60 | AY14: 2 | BA14: 0 | BB14: L | BC14: #N/A | BD14: #N/A | BE14: #N/A | BF14: #N/A | BG14: #N/A | BH14: #N/A | BI14: #N/A
A15: =I15&J15 -> 462734501762617 | B15: =_xlfn.CONCAT(T15,R15) -> GP485051-001B825 | C15: 1079768788 | D15: 10 | F15: Z005396H | G15: Z004M21N | H15: NB | I15: 46273 | J15: 4501762617 | K15: 90 | L15: X002178424 | M15: 749A | P15: 46273 | R15: B825 | S15: SBN1 | T15: GP485051-001 | U15: SHELL OMALA S5 WIND SYNTHETIC_ 20L | V15: 40 | W15: L | X15: L | Y15: 922.13 | Z15: ZBR | AA15: DQ | AE15: 34031900 | AF15: 2 | AG15: 2 | AH15: 0 | AJ15: 1 | AK15: 0 | AL15: L | AM15: 46314 | AT15: ZR0000 | AV15: R | AX15: 60 | AY15: 2 | BA15: 0 | BB15: L | BC15: #N/A | BD15: #N/A | BE15: #N/A | BF15: #N/A | BG15: #N/A | BH15: #N/A | BI15: #N/A
A16: =I16&J16 -> 462744501762741 | B16: =_xlfn.CONCAT(T16,R16) -> A7B95001359966B864 | C16: 1080497383 | D16: 10 | F16: Z0055PSX | G16: Z0056RTP | H16: NB | I16: 46274 | J16: 4501762741 | K16: 10 | L16: 50091142 | M16: BRC9 | P16: 46274 | R16: B864 | S16: SAV1 | T16: A7B95001359966 | U16: PAS DE CHOQUE ADULTO OBS 303A CMOS | V16: 1 | W16: PC | X16: PC | Y16: 878.54 | Z16: ZBR | AA16: C0 | AE16: 90189096 | AF16: 2 | AG16: 0 | AH16: 0 | AJ16: 1 | AK16: 0 | AL16: PC | AM16: 46295 | AT16: ZR0000 | AV16: R | AX16: 0 | AY16: 0 | BA16: 0 | BB16: PC | BC16: #N/A | BD16: #N/A | BE16: #N/A | BF16: #N/A | BG16: #N/A | BH16: #N/A | BI16: #N/A
A17: =I17&J17 -> 462744501762743 | B17: =_xlfn.CONCAT(T17,R17) -> A7B95001359966B865 | C17: 1080497132 | D17: 10 | F17: Z0055PSX | G17: Z0056RTP | H17: NB | I17: 46274 | J17: 4501762743 | K17: 10 | L17: 50091142 | M17: BRC9 | P17: 46274 | R17: B865 | S17: STS1 | T17: A7B95001359966 | U17: PAS DE CHOQUE ADULTO OBS 303A CMOS | V17: 1 | W17: PC | X17: PC | Y17: 878.54 | Z17: ZBR | AA17: C0 | AE17: 90189096 | AF17: 2 | AG17: 0 | AH17: 0 | AJ17: 1 | AK17: 0 | AL17: PC | AM17: 46295 | AT17: ZR0000 | AV17: R | AX17: 0 | AY17: 0 | BA17: 0 | BB17: PC | BC17: #N/A | BD17: #N/A | BE17: #N/A | BF17: #N/A | BG17: #N/A | BH17: #N/A | BI17: #N/A
A18: =I18&J18 -> 462754501763067 | B18: =_xlfn.CONCAT(T18,R18) -> A7B95001359966B832 | C18: 1080497131 | D18: 10 | F18: Z0055PSX | G18: Z0056RTP | H18: NB | I18: 46275 | J18: 4501763067 | K18: 10 | L18: 50091142 | M18: BRC9 | P18: 46275 | R18: B832 | S18: SUV1 | T18: A7B95001359966 | U18: PAS DE CHOQUE ADULTO OBS 303A CMOS | V18: 1 | W18: PC | X18: PC | Y18: 878.54 | Z18: ZBR | AA18: C0 | AE18: 90189096 | AF18: 2 | AG18: 0 | AH18: 0 | AJ18: 1 | AK18: 0 | AL18: PC | AM18: 46295 | AT18: ZR0000 | AV18: R | AX18: 0 | AY18: 0 | BA18: 0 | BB18: PC | BC18: #N/A | BD18: #N/A | BE18: #N/A | BF18: #N/A | BG18: #N/A | BH18: #N/A | BI18: #N/A
A19: =I19&J19 -> 462794300012000 | B19: =_xlfn.CONCAT(T19,R19) -> GP371842B867 | C19: 1080594830 | D19: 90 | F19: Z004B5DX | G19: Z005AMNR | H19: UB | I19: 46279 | J19: 4300012000 | K19: 60 | M19: 7499 | N19: B8D1 | O19: 2N01 | P19: 46279 | R19: B867 | S19: SVM3 | T19: GP371842 | U19: PROPORTIONAL VALVE 50-25L/MIN 10VDC | V19: 3 | W19: PC | X19: PC | Y19: 0 | Z19: ZBR | AB19: N_IMP | AC19: Q | AD19: PARTPEC | AE19: 84812090 | AF19: 0 | AG19: 1 | AH19: 0 | AI19: ZBRW06_QUA | AJ19: 2 | AK19: 3 | AL19: PC | AM19: 46302 | AN19: 46296 | AO19: 46296 | AP19: 46300 | AQ19: 46300 | AR19: 46302 | AS19: 46304 | AT19: RM2000 | AV19: R | AX19: 33 | AY19: 2 | BA19: 0 | BB19: PC | BC19: #N/A | BD19: #N/A | BE19: #N/A | BF19: #N/A | BG19: #N/A | BH19: #N/A | BI19: #N/A
A20: =I20&J20 -> 462794300012001 | B20: =_xlfn.CONCAT(T20,R20) -> GP371842B857 | C20: 1080594829 | D20: 80 | F20: Z004B5DX | G20: Z005AMNR | H20: UB | I20: 46279 | J20: 4300012001 | K20: 40 | M20: 7499 | N20: B8D1 | O20: 2N01 | P20: 46279 | R20: B857 | S20: SVS2 | T20: GP371842 | U20: PROPORTIONAL VALVE 50-25L/MIN 10VDC | V20: 3 | W20: PC | X20: PC | Y20: 0 | Z20: ZBR | AB20: N_IMP | AC20: Q | AD20: PARTPEC | AE20: 84812090 | AF20: 0 | AG20: 1 | AH20: 0 | AI20: ZBRW06_QUA | AJ20: 2 | AK20: 3 | AL20: PC | AM20: 46302 | AN20: 46296 | AO20: 46296 | AP20: 46300 | AQ20: 46300 | AR20: 46302 | AS20: 46304 | AT20: RM2000 | AV20: R | AX20: 33 | AY20: 2 | BA20: 0 | BB20: PC | BC20: #N/A | BD20: #N/A | BE20: #N/A | BF20: #N/A | BG20: #N/A | BH20: #N/A | BI20: #N/A
A21: =I21&J21 -> 462794300012002 | B21: =_xlfn.CONCAT(T21,R21) -> GP468401B856 | C21: 1080594715 | D21: 70 | F21: Z004B5DX | G21: Z005AMNR | H21: UB | I21: 46279 | J21: 4300012002 | K21: 70 | M21: 7499 | N21: B8D1 | O21: 2N01 | P21: 46279 | R21: B856 | S21: SVS1 | T21: GP468401 | U21: PISTON GUIDE RING 160/2.5X25 C380 | V21: 20 | W21: PC | X21: PC | Y21: 0 | Z21: ZBR | AB21: N_IMP | AC21: Q | AD21: PARTPEC | AE21: 39269090 | AF21: 0 | AG21: 1 | AH21: 0 | AI21: ZBRW06_QUA | AJ21: 1 | AK21: 0 | AL21: PC | AM21: 46428 | AN21: 46477 | AO21: 46422 | AP21: 46426 | AQ21: 46426 | AR21: 46428 | AS21: 46428 | AT21: RM2000 | AV21: R | AX21: 0 | AY21: 0 | BA21: 0 | BB21: PC | BC21: #N/A | BD21: #N/A | BE21: #N/A | BF21: #N/A | BG21: #N/A | BH21: #N/A | BI21: #N/A
A22: =I22&J22 -> 462794300012003 | B22: =_xlfn.CONCAT(T22,R22) -> GP325616B832 | C22: 1080587073 | D22: 10 | F22: Z00418VH | G22: Z005AMNR | H22: UB | I22: 46279 | J22: 4300012003 | K22: 10 | M22: 7499 | N22: B825 | O22: SBN1 | P22: 46279 | R22: B832 | S22: SUV1 | T22: GP325616 | U22: VALVULA PROPORCIONAL 170L/MIN 315BAR 4/3 | V22: 1 | W22: PC | X22: PC | Y22: 0 | Z22: ZBR | AB22: N_IMP | AC22: Q | AD22: PARTPEC | AE22: 84812090 | AF22: 0 | AG22: 1 | AH22: 0 | AJ22: 1 | AK22: 1 | AL22: PC | AM22: 46308 | AN22: 46308 | AO22: 46308 | AP22: 46308 | AQ22: 46308 | AR22: 46308 | AS22: 46310 | AT22: RM2000 | AV22: R | AX22: 33 | AY22: 2 | BA22: 1 | BB22: PC | BC22: #N/A | BD22: #N/A | BE22: #N/A | BF22: #N/A | BG22: #N/A | BH22: #N/A | BI22: #N/A
A23: =I23&J23 -> 462794300012011 | B23: =_xlfn.CONCAT(T23,R23) -> GP553917B857 | C23: 1080586343 | D23: 10 | F23: Z00418BM | G23: Z005AMNR | H23: UB | I23: 46279 | J23: 4300012011 | K23: 10 | M23: 7499 | N23: B855 | O23: SSL2 | P23: 46279 | R23: B857 | S23: SVS2 | T23: GP553917 | U23: SPD_PHO_TTC-6-2-HC-24DC-UT-I_2908438 | V23: 1 | W23: PC | X23: PC | Y23: 0 | Z23: ZBR | AB23: N_IMP | AC23: Q | AD23: PARTPEC | AE23: 85363090 | AF23: 0 | AG23: 1 | AH23: 0 | AJ23: 1 | AK23: 1 | AL23: PC | AM23: 46358 | AN23: 46358 | AO23: 46358 | AP23: 46358 | AQ23: 46358 | AR23: 46358 | AS23: 46380 | AT23: RM2000 | AV23: R | AX23: 84 | AY23: 16 | BA23: 1 | BB23: PC | BC23: #N/A | BD23: #N/A | BE23: #N/A | BF23: #N/A | BG23: #N/A | BH23: #N/A | BI23: #N/A
A24: =I24&J24 -> 462794300012012 | B24: =_xlfn.CONCAT(T24,R24) -> 218150B832 | C24: 1080621402 | D24: 10 | F24: Z00416BT | G24: Z005AMNR | H24: UB | I24: 46279 | J24: 4300012012 | K24: 10 | M24: 7499 | N24: B825 | O24: SBN1 | P24: 46279 | R24: B832 | S24: SUV1 | T24: 218150 | U24: LUVAS DE LATEX - CAIXA 100 UDS. | V24: 10 | W24: PC | X24: PC | Y24: 0 | Z24: ZBR | AD24: USOCONSUM | AE24: 40151900 | AF24: 2 | AG24: 0 | AH24: 0 | AJ24: 1 | AK24: 10 | AL24: PC | AM24: 46314 | AN24: 46314 | AO24: 46314 | AP24: 46314 | AQ24: 46314 | AR24: 46314 | AS24: 46316 | AT24: RM2000 | AV24: R | AX24: 33 | AY24: 2 | BA24: 10 | BB24: PC | BC24: #N/A | BD24: #N/A | BE24: #N/A | BF24: #N/A | BG24: #N/A | BH24: #N/A | BI24: #N/A
A25: =I25&J25 -> 462794501763492 | B25: =_xlfn.CONCAT(T25,R25) -> GP486978-004B856 | C25: 1080187716 | D25: 10 | F25: Z005396H | G25: Z00488YE | H25: NB | I25: 46279 | J25: 4501763492 | K25: 20 | L25: X002178424 | M25: 749A | P25: 46279 | R25: B856 | S25: SVS1 | T25: GP486978-004 | U25: SHELL TELLUS S2VX32 FINE HYDR OIL 208,2L | V25: 208.2 | W25: L | X25: L | Y25: 3903.01 | Z25: ZBR | AA25: TD | AE25: 27101932 | AF25: 2 | AG25: 2 | AH25: 0 | AJ25: 1 | AK25: 0 | AL25: L | AM25: 46309 | AT25: ZR0000 | AV25: R | AX25: 60 | AY25: 2 | BA25: 0 | BB25: L | BC25: #N/A | BD25: #N/A | BE25: #N/A | BF25: #N/A | BG25: #N/A | BH25: #N/A | BI25: #N/A
A26: =I26&J26 -> 462804501763579 | B26: =_xlfn.CONCAT(T26,R26) -> A7B95001359702B865 | C26: 1080604255 | D26: 50 | F26: Z004YARF | G26: Z0056RTP | H26: NB | I26: 46280 | J26: 4501763579 | K26: 50 | L26: 50091142 | M26: BRC9 | P26: 46280 | R26: B865 | S26: 0003 | T26: A7B95001359702 | U26: ESTICADOR PET 13/16/19MM / MOSKA | V26: 1 | W26: PC | X26: PC | Y26: 389.82 | Z26: ZBR | AA26: C0 | AE26: 84224090 | AF26: 2 | AG26: 0 | AH26: 0 | AJ26: 1 | AK26: 0 | AL26: PC | AM26: 46295 | AT26: ZR0000 | AV26: R | AX26: 0 | AY26: 0 | BA26: 0 | BB26: PC | BC26: #N/A | BD26: #N/A | BE26: #N/A | BF26: #N/A | BG26: #N/A | BH26: #N/A | BI26: #N/A
A27: =I27&J27 -> 462804501763606 | B27: =_xlfn.CONCAT(T27,R27) -> A7B95001359703B865 | C27: 1080604248 | D27: 40 | F27: Z004YARF | G27: Z0056RTP | H27: NB | I27: 46280 | J27: 4501763606 | K27: 40 | L27: X002120844 | M27: BRC9 | P27: 46280 | R27: B865 | S27: 0003 | T27: A7B95001359703 | U27: CORTA TUBO PVC 42MM 3559042000 VONDER | V27: 1 | W27: PC | X27: PC | Y27: 23.89 | Z27: ZBR | AA27: C7 | AE27: 82034000 | AF27: 2 | AG27: 2 | AH27: 0 | AJ27: 1 | AK27: 0 | AL27: PC | AM27: 46295 | AT27: ZR0000 | AV27: R | AX27: 0 | AY27: 0 | BA27: 0 | BB27: PC | BC27: #N/A | BD27: #N/A | BE27: #N/A | BF27: #N/A | BG27: #N/A | BH27: #N/A | BI27: #N/A
A28: =I28&J28 -> 462804501763612 | B28: =_xlfn.CONCAT(T28,R28) -> A7B95001359703B864 | C28: 1080604247 | D28: 40 | F28: Z004YARF | G28: Z0056RTP | H28: NB | I28: 46280 | J28: 4501763612 | K28: 40 | L28: X002120844 | M28: BRC9 | P28: 46280 | R28: B864 | S28: SAV1 | T28: A7B95001359703 | U28: CORTA TUBO PVC 42MM 3559042000 VONDER | V28: 1 | W28: PC | X28: PC | Y28: 23.89 | Z28: ZBR | AA28: C7 | AE28: 82034000 | AF28: 2 | AG28: 2 | AH28: 0 | AJ28: 1 | AK28: 0 | AL28: PC | AM28: 46295 | AT28: ZR0000 | AV28: R | AX28: 0 | AY28: 0 | BA28: 0 | BB28: PC | BC28: #N/A | BD28: #N/A | BE28: #N/A | BF28: #N/A | BG28: #N/A | BH28: #N/A | BI28: #N/A
A29: =I29&J29 -> 462824300012037 | B29: =_xlfn.CONCAT(T29,R29) -> 109537B867 | C29: 1080662830 | D29: 10 | F29: Z004149W | G29: Z005AMNR | H29: UB | I29: 46282 | J29: 4300012037 | K29: 10 | M29: 7499 | N29: B8D1 | O29: 2N01 | P29: 46282 | R29: B867 | S29: SVM3 | T29: 109537 | U29: SENSOR PRESSÃO 0-250B DANFOSS V47 | V29: 2 | W29: PC | X29: PC | Y29: 0 | Z29: ZBR | AB29: N_IMP | AC29: Q | AD29: PARTPEC | AE29: 90262090 | AF29: 0 | AG29: 1 | AH29: 0 | AI29: ZBRW06_QUA | AJ29: 2 | AK29: 2 | AL29: PC | AM29: 46309 | AN29: 46302 | AO29: 46302 | AP29: 46304 | AQ29: 46304 | AR29: 46309 | AS29: 46311 | AT29: RM2000 | AV29: R | AX29: 33 | AY29: 2 | BA29: 0 | BB29: PC | BC29: #N/A | BD29: #N/A | BE29: #N/A | BF29: #N/A | BG29: #N/A | BH29: #N/A | BI29: #N/A
A30: =I30&J30 -> 462824300012038 | B30: =_xlfn.CONCAT(T30,R30) -> 109537B857 | C30: 1080662829 | D30: 10 | F30: Z004149W | G30: Z005AMNR | H30: UB | I30: 46282 | J30: 4300012038 | K30: 10 | M30: 7499 | N30: B8D1 | O30: 2N01 | P30: 46282 | R30: B857 | S30: SVS2 | T30: 109537 | U30: SENSOR PRESSÃO 0-250B DANFOSS V47 | V30: 2 | W30: PC | X30: PC | Y30: 0 | Z30: ZBR | AB30: N_IMP | AC30: Q | AD30: PARTPEC | AE30: 90262090 | AF30: 0 | AG30: 1 | AH30: 0 | AI30: ZBRW06_QUA | AJ30: 2 | AK30: 2 | AL30: PC | AM30: 46309 | AN30: 46302 | AO30: 46302 | AP30: 46304 | AQ30: 46304 | AR30: 46309 | AS30: 46311 | AT30: RM2000 | AV30: R | AX30: 33 | AY30: 2 | BA30: 0 | BB30: PC | BC30: #N/A | BD30: #N/A | BE30: #N/A | BF30: #N/A | BG30: #N/A | BH30: #N/A | BI30: #N/A
A31: =I31&J31 -> 462824501763954 | B31: =_xlfn.CONCAT(T31,R31) -> A9B00019165B867 | C31: 1080640509 | D31: 10 | F31: Z004158A | G31: Z00488YE | H31: NB | I31: 46282 | J31: 4501763954 | K31: 10 | L31: X002178424 | M31: 749A | P31: 46282 | R31: B867 | S31: SVM3 | T31: A9B00019165 | U31: GREASE SHELL RHODINA, 5 KG, BBZ | V31: 490 | W31: KG | X31: KG | Y31: 873.01 | Z31: ZBR | AA31: DP | AE31: 34031900 | AF31: 2 | AG31: 2 | AH31: 0 | AJ31: 1 | AK31: 0 | AL31: KG | AM31: 46296 | AT31: ZR0000 | AV31: R | AX31: 60 | AY31: 2 | BA31: 0 | BB31: KG | BC31: #N/A | BD31: #N/A | BE31: #N/A | BF31: #N/A | BG31: #N/A | BH31: #N/A | BI31: #N/A
A32: =I32&J32 -> 462824300012043 | B32: =_xlfn.CONCAT(T32,R32) -> 50834B825 | C32: 1080682316 | D32: 10 | F32: Z00414MR | G32: Z005AMNR | H32: UB | I32: 46282 | J32: 4300012043 | K32: 10 | M32: 7499 | N32: B8D1 | O32: 2N01 | P32: 46282 | R32: B825 | S32: SBN1 | T32: 50834 | U32: VALVULA ANTI-RET. RHZ20SRPEFLEX VO604462 | V32: 2 | W32: PC | X32: PC | Y32: 0 | Z32: ZBR | AB32: N_IMP | AC32: Q | AD32: PARTPEC | AE32: 84813000 | AF32: 0 | AG32: 1 | AH32: 0 | AI32: ZBRW05_SEX | AJ32: 1 | AK32: 0 | AL32: PC | AM32: 46315 | AN32: 46304 | AO32: 46304 | AP32: 46309 | AQ32: 46309 | AR32: 46311 | AS32: 46315 | AT32: RM2000 | AV32: R | AX32: 33 | AY32: 2 | BA32: 0 | BB32: PC | BC32: #N/A | BD32: #N/A | BE32: #N/A | BF32: #N/A | BG32: #N/A | BH32: #N/A | BI32: #N/A
A33: =I33&J33 -> 462824300012045 | B33: =_xlfn.CONCAT(T33,R33) -> GP081087B825 | C33: 1080682365 | D33: 10 | F33: Z00414MR | G33: Z005AMNR | H33: UB | I33: 46282 | J33: 4300012045 | K33: 10 | M33: 7499 | N33: B8D1 | O33: 2N01 | P33: 46282 | R33: B825 | S33: SBN1 | T33: GP081087 | U33: HOIST SUPPORT PIN | V33: 220 | W33: PC | X33: PC | Y33: 0 | Z33: ZBR | AB33: N_IMP | AC33: Q | AD33: PARTPEC | AE33: 73269090 | AF33: 0 | AG33: 1 | AH33: 0 | AI33: ZBRW05_SEX | AJ33: 1 | AK33: 0 | AL33: PC | AM33: 46343 | AN33: 46468 | AO33: 46335 | AP33: 46337 | AQ33: 46337 | AR33: 46339 | AS33: 46339 | AT33: RM2000 | AV33: R | AX33: 0 | AY33: 0 | BA33: 0 | BB33: PC | BC33: #N/A | BD33: #N/A | BE33: #N/A | BF33: #N/A | BG33: #N/A | BH33: #N/A | BI33: #N/A
A34: =I34&J34 -> 462824300012048 | B34: =_xlfn.CONCAT(T34,R34) -> GP485135B857 | C34: 1080662653 | D34: 40 | F34: Z004149W | G34: Z005AMNR | H34: UB | I34: 46282 | J34: 4300012048 | K34: 40 | M34: 7499 | N34: B8D1 | O34: 2N01 | P34: 46282 | R34: B857 | S34: SVS2 | T34: GP485135 | U34: CABLE WA79 3.4 | V34: 2 | W34: PC | X34: PC | Y34: 0 | Z34: ZBR | AB34: N_IMP | AC34: Q | AD34: PARTPEC | AE34: 85444200 | AF34: 0 | AG34: 1 | AH34: 0 | AI34: ZBRW06_QUA | AJ34: 2 | AK34: 1 | AL34: PC | AM34: 46302 | AN34: 46302 | AO34: 46296 | AP34: 46300 | AQ34: 46300 | AR34: 46302 | AS34: 46304 | AT34: RM2000 | AV34: R | AX34: 33 | AY34: 2 | BA34: 0 | BB34: PC | BC34: #N/A | BD34: #N/A | BE34: #N/A | BF34: #N/A | BG34: #N/A | BH34: #N/A | BI34: #N/A
A35: =I35&J35 -> 462824300012049 | B35: =_xlfn.CONCAT(T35,R35) -> GP315334B867 | C35: 1080662652 | D35: 10 | F35: Z004149W | G35: Z005AMNR | H35: UB | I35: 46282 | J35: 4300012049 | K35: 10 | M35: 7499 | N35: B8D1 | O35: 2N01 | P35: 46282 | R35: B867 | S35: SVM3 | T35: GP315334 | U35: INDUCTIVE SENSOR M18 + CABLE WS101 3.3MW | V35: 2 | W35: PC | X35: PC | Y35: 0 | Z35: ZBR | AB35: N_IMP | AC35: Q | AD35: PARTPEC | AE35: 90318099 | AF35: 0 | AG35: 1 | AH35: 0 | AI35: ZBRW06_QUA | AJ35: 1 | AK35: 0 | AL35: PC | AM35: 46314 | AN35: 46468 | AO35: 46302 | AP35: 46304 | AQ35: 46304 | AR35: 46309 | AS35: 46311 | AT35: RM2000 | AV35: R | AX35: 33 | AY35: 2 | BA35: 0 | BB35: PC | BC35: #N/A | BD35: #N/A | BE35: #N/A | BF35: #N/A | BG35: #N/A | BH35: #N/A | BI35: #N/A
A36: =I36&J36 -> 461594300008405 | B36: =_xlfn.CONCAT(T36,R36) -> GP583604B838 | D36: 0 | E36: 42294203 | F36: DMC_Z00540RF | G36: DMC_Z00540RF | H36: UB | I36: 46159 | J36: 4300008405 | K36: 70 | M36: 7499 | N36: B8D1 | O36: 2N01 | P36: 46159 | R36: B838 | S36: SVA1 | T36: GP583604 | U36: BUSHING D23 H40 | V36: 4 | W36: PC | X36: PC | Y36: 0 | Z36: ZBR | AB36: N_IMP | AC36: Q | AD36: PARTPEC | AE36: 73269090 | AF36: 0 | AG36: 1 | AH36: 0 | AI36: ZBRW06_QUA | AJ36: 1 | AK36: 0 | AL36: PC | AM36: 47177 | AN36: 47171 | AO36: 47171 | AP36: 47175 | AQ36: 47175 | AR36: 47177 | AS36: 47177 | AT36: RM2000 | AV36: R | AX36: 0 | AY36: 0 | BA36: 0 | BB36: PC | BC36: #N/A | BD36: #N/A | BE36: #N/A | BF36: #N/A | BG36: #N/A | BH36: #N/A | BI36: #N/A
A37: =I37&J37 -> 461594300008407 | B37: =_xlfn.CONCAT(T37,R37) -> GP104233B832 | D37: 0 | E37: 42294278 | F37: DMC_Z00540RF | G37: DMC_Z00540RF | H37: UB | I37: 46159 | J37: 4300008407 | K37: 10 | M37: 7499 | N37: B8D1 | O37: 2N01 | P37: 46159 | R37: B832 | S37: SUV1 | T37: GP104233 | U37: FLOOR CLIP WIDE WASHER M8 | V37: 124 | W37: PC | X37: PC | Y37: 0 | Z37: ZBR | AB37: N_NAC | AC37: Q | AD37: PARTPEC | AE37: 73182200 | AF37: 0 | AG37: 0 | AH37: 0 | AI37: ZBRW05_SEX | AJ37: 2 | AK37: 124 | AL37: PC | AM37: 46262 | AN37: 46258 | AO37: 46258 | AP37: 46260 | AQ37: 46260 | AR37: 46262 | AS37: 46262 | AT37: RM2000 | AV37: R | AX37: 0 | AY37: 0 | BA37: 0 | BB37: PC | BC37: #N/A | BD37: #N/A | BE37: #N/A | BF37: #N/A | BG37: SERVICE BULLETIN | BH37: 1057403 | BI37: SERVICE BULLETIN
A38: =I38&J38 -> 461594300008408 | B38: =_xlfn.CONCAT(T38,R38) -> GP062392B833 | D38: 0 | E38: 42294282 | F38: DMC_Z00540RF | G38: DMC_Z00540RF | H38: UB | I38: 46159 | J38: 4300008408 | K38: 20 | M38: 7499 | N38: B8D1 | O38: 2N01 | P38: 46159 | R38: B833 | S38: SUV2 | T38: GP062392 | U38: BOLT ISO4014 M16X90 10.9 FLZNL NC 1000H | V38: 39 | W38: PC | X38: PC | Y38: 0 | Z38: ZBR | AB38: N_IMP | AC38: Q | AD38: PARTPEC | AE38: 73181500 | AF38: 0 | AG38: 1 | AH38: 0 | AI38: ZBRW05_SEX | AJ38: 1 | AK38: 0 | AL38: PC | AM38: 46264 | AN38: 46258 | AO38: 46258 | AP38: 46260 | AQ38: 46260 | AR38: 46262 | AS38: 46262 | AT38: RM2000 | AV38: R | AX38: 0 | AY38: 0 | BA38: 0 | BB38: PC | BC38: 80022998 | BD38: 39 | BE38: 46230 | BF38: C | BG38: SERVICE BULLETIN | BH38: 1057403 | BI38: SERVICE BULLETIN
A39: =I39&J39 -> 461594300008410 | B39: =_xlfn.CONCAT(T39,R39) -> GP104233B865 | D39: 0 | E39: 42294306 | F39: DMC_Z00540RF | G39: DMC_Z00540RF | H39: UB | I39: 46159 | J39: 4300008410 | K39: 20 | M39: 7499 | N39: B8D1 | O39: 2N01 | P39: 46159 | R39: B865 | S39: STS1 | T39: GP104233 | U39: FLOOR CLIP WIDE WASHER M8 | V39: 500 | W39: PC | X39: PC | Y39: 0 | Z39: ZBR | AB39: N_NAC | AC39: Q | AD39: PARTPEC | AE39: 73182200 | AF39: 0 | AG39: 0 | AH39: 0 | AI39: ZBRW05_SEX | AJ39: 2 | AK39: 500 | AL39: PC | AM39: 47172 | AN39: 47168 | AO39: 47168 | AP39: 47170 | AQ39: 47170 | AR39: 47172 | AS39: 47172 | AT39: RM2000 | AV39: R | AX39: 0 | AY39: 0 | BA39: 0 | BB39: PC | BC39: #N/A | BD39: #N/A | BE39: #N/A | BF39: #N/A | BG39: SERVICE BULLETIN | BH39: 1057403 | BI39: SERVICE BULLETIN
A40: =I40&J40 -> 461594300008411 | B40: =_xlfn.CONCAT(T40,R40) -> GP569984B864 | D40: 0 | E40: 42294950 | F40: DMC_Z00540RF | G40: DMC_Z00540RF | H40: UB | I40: 46159 | J40: 4300008411 | K40: 10 | M40: 7499 | N40: B8D1 | O40: 2N01 | P40: 46159 | R40: B864 | S40: SAV1 | T40: GP569984 | U40: GRATING OVER STATOR CABLES STR 2-A | V40: 2 | W40: PC | X40: PC | Y40: 0 | Z40: ZBR | AB40: N_IMP | AC40: Q | AD40: PARTPEC | AE40: 73269090 | AF40: 0 | AG40: 1 | AH40: 0 | AI40: ZBRW06_QUA | AJ40: 1 | AK40: 0 | AL40: PC | AM40: 47177 | AN40: 47171 | AO40: 47171 | AP40: 47175 | AQ40: 47175 | AR40: 47177 | AS40: 47177 | AT40: RM2000 | AV40: R | AX40: 0 | AY40: 0 | BA40: 0 | BB40: PC | BC40: #N/A | BD40: #N/A | BE40: #N/A | BF40: #N/A | BG40: SERVICE BULLETIN | BH40: GBELOTI | BI40: SB - B33152003 - Generator power cables tray modification - M064
...

Sheet LRR
A1: conc | B1: Material | C1: Área MRP | D1: Área MRP centro | E1: Perfil MRP | F1: Tipo de MRP | G1: Planejador MRP | H1: Grupo MRP | I1: Ponto reabastec. | J1: Ciclo MRP | K1: Horizonte plan.fixo | L1: Tamanho do lote MRP | M1: Perf.arredond. | N1: Valor arredondamento | O1: Tamanho mínimo lote | P1: Tamanho máximo lote | Q1: Estoque máximo | R1: Tmp.ciclo trabalho | S1: Refugo conjunto (%) | T1: Suprimento especial | U1: Depósito de produção | V1: Depós.suprimto.ext. | W1: Calendário planj. | X1: Estoque de segurança | Y1: Perfil cobertura | Z1: Tmp.seg.nec./cob.re. | AA1: Tamanho fixo do lote | AB1: CstsFixos por pedido | AC1: CódCustosArmazenagem | AD1: Grau atend. (%) | AE1: Perfil previsão | AF1: Mat.ref. - consumo | AG1: Cons.área MRP ref. | AH1: Data até | AI1: Multiplicador | AJ1: Marc.p/elimin. | AK1: Perf.per.períod.seg. | AL1: MRP necs.dependentes | AM1: Reinicializ.autom. | AN1: Status atualização | AO1: Fatores de correção | AP1: Código margem seg. | AQ1: Relevante para APO | AR1: PrzEntrPrev. | AS1: Consid.prazo entrega previsto | AT1: Modificado por | AU1: Changed on | AV1: Hora de modificação
A2: =_xlfn.CONCAT(B2,D2) -> 50013B832 | B2: 50013 | C2: B832SUV1 | D2: B832 | F2: ZY | G2: ZRP | H2: ZS20 | I2: 3 | K2: 0 | L2: WB | M2: Z001 | N2: 0 | O2: 0 | P2: 0 | Q2: 0 | R2: 0 | S2: 0 | T2: SE | U2: SUV1 | V2: SUV1 | X2: 1 | Z2: 0 | AA2: 0 | AB2: 0 | AD2: 0 | AI2: 0 | AJ2: X | AN2: D | AR2: 0 | AT2: DMC_Z00540RF | AU2: 46275 | AV2: 0.60385417
A3: =_xlfn.CONCAT(B3,D3) -> 50013B838 | B3: 50013 | C3: B838SVA1 | D3: B838 | F3: ZY | G3: ZRP | H3: ZS20 | I3: 2 | K3: 0 | L3: WB | M3: Z001 | N3: 0 | O3: 0 | P3: 0 | Q3: 0 | R3: 0 | S3: 0 | T3: SE | U3: SVA1 | V3: SVA1 | X3: 1 | Z3: 0 | AA3: 0 | AB3: 0 | AD3: 0 | AI3: 0 | AJ3: X | AN3: D | AR3: 0 | AT3: DMC_Z00540RF | AU3: 46275 | AV3: 0.60465278
A4: =_xlfn.CONCAT(B4,D4) -> 50096B857 | B4: 50096 | C4: B857SVS2 | D4: B857 | F4: ZY | G4: ZRP | H4: ZS20 | I4: 1 | K4: 0 | L4: WB | M4: Z001 | N4: 0 | O4: 0 | P4: 0 | Q4: 0 | R4: 0 | S4: 0 | T4: SE | U4: SVS2 | V4: SVS2 | X4: 1 | Z4: 0 | AA4: 0 | AB4: 0 | AD4: 0 | AI4: 0 | AJ4: X | AN4: D | AR4: 0 | AT4: DMC_Z00540RF | AU4: 46275 | AV4: 0.60532407
A5: =_xlfn.CONCAT(B5,D5) -> 50116B832 | B5: 50116 | C5: B832SUV1 | D5: B832 | F5: PD | G5: ZRP | H5: ZS20 | I5: 2 | K5: 0 | L5: WB | M5: Z001 | N5: 0 | O5: 0 | P5: 0 | Q5: 0 | R5: 0 | S5: 0 | T5: SE | U5: SUV1 | V5: SUV1 | X5: 2 | Z5: 0 | AA5: 0 | AB5: 0 | AD5: 0 | AI5: 0 | AJ5: X | AN5: D | AR5: 0 | AT5: DMC_Z00540RF | AU5: 46275 | AV5: 0.60385417
A6: =_xlfn.CONCAT(B6,D6) -> 50233B825 | B6: 50233 | C6: B825SBN1 | D6: B825 | F6: ZY | G6: ZRP | H6: ZS20 | I6: 2 | K6: 0 | L6: WB | M6: Z001 | N6: 0 | O6: 0 | P6: 0 | Q6: 0 | R6: 0 | S6: 0 | T6: SE | U6: SBN1 | V6: SBN1 | X6: 1 | Z6: 0 | AA6: 0 | AB6: 0 | AD6: 0 | AI6: 0 | AJ6: X | AN6: D | AR6: 0 | AT6: DMC_Z00540RF | AU6: 46275 | AV6: 0.60354167
A7: =_xlfn.CONCAT(B7,D7) -> 50234B832 | B7: 50234 | C7: B832SUV1 | D7: B832 | F7: ZY | G7: ZRP | H7: ZS20 | I7: 2 | K7: 0 | L7: WB | M7: Z001 | N7: 0 | O7: 0 | P7: 0 | Q7: 0 | R7: 0 | S7: 0 | T7: SE | U7: SUV1 | V7: SUV1 | X7: 1 | Z7: 0 | AA7: 0 | AB7: 0 | AD7: 0 | AI7: 0 | AJ7: X | AN7: D | AR7: 0 | AT7: DMC_Z00540RF | AU7: 46275 | AV7: 0.62333333
A8: =_xlfn.CONCAT(B8,D8) -> 50234B864 | B8: 50234 | C8: B864SAV1 | D8: B864 | F8: ZY | G8: ZRP | H8: ZS20 | I8: 2 | K8: 0 | L8: WB | M8: Z001 | N8: 0 | O8: 0 | P8: 0 | Q8: 0 | R8: 0 | S8: 0 | T8: SE | U8: SAV1 | V8: SAV1 | X8: 1 | Z8: 0 | AA8: 0 | AB8: 0 | AD8: 0 | AI8: 0 | AJ8: X | AN8: D | AR8: 0 | AT8: DMC_Z00540RF | AU8: 46275 | AV8: 0.6265162
A9: =_xlfn.CONCAT(B9,D9) -> 50234B865 | B9: 50234 | C9: B865STS1 | D9: B865 | F9: ZY | G9: ZRP | H9: ZS20 | I9: 2 | K9: 0 | L9: WB | M9: Z001 | N9: 0 | O9: 0 | P9: 0 | Q9: 0 | R9: 0 | S9: 0 | T9: SE | U9: STS1 | V9: STS1 | X9: 1 | Z9: 0 | AA9: 0 | AB9: 0 | AD9: 0 | AI9: 0 | AJ9: X | AN9: D | AR9: 0 | AT9: DMC_Z00540RF | AU9: 46275 | AV9: 0.62665509
A10: =_xlfn.CONCAT(B10,D10) -> 50235B832 | B10: 50235 | C10: B832SUV1 | D10: B832 | F10: ZY | G10: ZRP | H10: ZS20 | I10: 2 | K10: 0 | L10: WB | M10: Z001 | N10: 0 | O10: 0 | P10: 0 | Q10: 0 | R10: 0 | S10: 0 | T10: SE | U10: SUV1 | V10: SUV1 | X10: 1 | Z10: 0 | AA10: 0 | AB10: 0 | AD10: 0 | AI10: 0 | AJ10: X | AN10: D | AR10: 0 | AT10: DMC_Z00540RF | AU10: 46275 | AV10: 0.60391204
A11: =_xlfn.CONCAT(B11,D11) -> 50235B838 | B11: 50235 | C11: B838SVA1 | D11: B838 | F11: ZY | G11: ZRP | H11: ZS20 | I11: 2 | K11: 0 | L11: WB | M11: Z001 | N11: 0 | O11: 0 | P11: 0 | Q11: 0 | R11: 0 | S11: 0 | T11: SE | U11: SVA1 | V11: SVA1 | X11: 1 | Z11: 0 | AA11: 0 | AB11: 0 | AD11: 0 | AI11: 0 | AJ11: X | AN11: D | AR11: 0 | AT11: DMC_Z00540RF | AU11: 46275 | AV11: 0.60471065
A12: =_xlfn.CONCAT(B12,D12) -> 50235B856 | B12: 50235 | C12: B856SVS1 | D12: B856 | F12: ZY | G12: ZRP | H12: ZS20 | I12: 1 | K12: 0 | L12: WB | M12: Z001 | N12: 0 | O12: 0 | P12: 0 | Q12: 0 | R12: 0 | S12: 0 | T12: SE | U12: SVS1 | V12: SVS1 | X12: 1 | Z12: 0 | AA12: 0 | AB12: 0 | AD12: 0 | AI12: 0 | AJ12: X | AN12: D | AR12: 0 | AT12: DMC_Z00540RF | AU12: 46275 | AV12: 0.60523148
A13: =_xlfn.CONCAT(B13,D13) -> 50235B857 | B13: 50235 | C13: B857SVS2 | D13: B857 | F13: ZY | G13: ZRP | H13: ZS20 | I13: 2 | K13: 0 | L13: WB | M13: Z001 | N13: 0 | O13: 0 | P13: 0 | Q13: 0 | R13: 0 | S13: 0 | T13: SE | U13: SVS2 | V13: SVS2 | X13: 1 | Z13: 0 | AA13: 0 | AB13: 0 | AD13: 0 | AI13: 0 | AJ13: X | AN13: D | AR13: 0 | AT13: DMC_Z00540RF | AU13: 46275 | AV13: 0.60532407
... A190: =_xlfn.CONCAT(B190,D190) -> 1U6001JDE32B838 | B190: 1U6001JDE32 | C190: B838SVA1 | D190: B838 | F190: ZY | G190: ZRP | H190: ZS20 | I190: 1 | K190: 0 | L190: WB | M190: Z001 | N190: 0 | O190: 0 | P190: 0 | Q190: 0 | R190: 0 | S190: 0 | T190: SE | U190: SVA1 | V190: SVA1 | X190: 1 | Z190: 0 | AA190: 0 | AB190: 0 | AD190: 0 | AI190: 0 | AJ190: X | AN190: D | AR190: 0 | AT190: DMC_Z00540RF | AU190: 46275 | AV190: 0.62418981
A191: =_xlfn.CONCAT(B191,D191) -> A9B00019165B832 | B191: A9B00019165 | C191: B832SUV1 | D191: B832 | F191: PD | G191: ZRP | H191: ZS10 | I191: 10 | K191: 0 | L191: WB | M191: Z005 | N191: 0 | O191: 0 | P191: 0 | Q191: 0 | R191: 0 | S191: 0 | U191: SUV1 | V191: SUV1 | X191: 10 | Z191: 0 | AA191: 0 | AB191: 0 | AD191: 0 | AI191: 0 | AJ191: X | AN191: D | AR191: 0 | AT191: DMC_Z00540RF | AU191: 46275 | AV191: 0.60386574
A192: =_xlfn.CONCAT(B192,D192) -> A9B10239097B825 | B192: A9B10239097 | C192: B825SBN1 | D192: B825 | F192: ZY | G192: ZRP | H192: ZS20 | I192: 2 | K192: 0 | L192: WB | M192: Z001 | N192: 0 | O192: 0 | P192: 0 | Q192: 0 | R192: 0 | S192: 0 | T192: SE | U192: SBN1 | V192: SBN1 | X192: 1 | Z192: 0 | AA192: 0 | AB192: 0 | AD192: 0 | AI192: 0 | AJ192: X | AN192: D | AR192: 0 | AT192: DMC_Z00540RF | AU192: 46275 | AV192: 0.62302083
A193: =_xlfn.CONCAT(B193,D193) -> A9B10239097B856 | B193: A9B10239097 | C193: B856SVS1 | D193: B856 | F193: ZY | G193: ZRP | H193: ZS20 | I193: 2 | K193: 0 | L193: WB | M193: Z001 | N193: 0 | O193: 0 | P193: 0 | Q193: 0 | R193: 0 | S193: 0 | T193: SE | U193: SVS1 | V193: SVS1 | X193: 1 | Z193: 0 | AA193: 0 | AB193: 0 | AD193: 0 | AI193: 0 | AJ193: X | AN193: D | AR193: 0 | AT193: DMC_Z00540RF | AU193: 46275 | AV193: 0.62490741
A194: =_xlfn.CONCAT(B194,D194) -> A9B10239097B867 | B194: A9B10239097 | C194: B867SVM3 | D194: B867 | F194: ZY | G194: ZRP | H194: ZS20 | I194: 2 | K194: 0 | L194: WB | M194: Z001 | N194: 0 | O194: 0 | P194: 0 | Q194: 0 | R194: 0 | S194: 0 | T194: SE | U194: SVM3 | V194: SVM3 | X194: 1 | Z194: 0 | AA194: 0 | AB194: 0 | AD194: 0 | AI194: 0 | AJ194: X | AN194: D | AR194: 0 | AT194: DMC_Z00540RF | AU194: 46275 | AV194: 0.62737269
A195: =_xlfn.CONCAT(B195,D195) -> AIS0253B825 | B195: AIS0253 | C195: B825SBN1 | D195: B825 | F195: ZY | G195: ZRP | H195: ZS20 | I195: 2 | K195: 0 | L195: WB | M195: Z001 | N195: 0 | O195: 0 | P195: 0 | Q195: 0 | R195: 0 | S195: 0 | T195: SE | U195: SBN1 | V195: SBN1 | X195: 1 | Z195: 0 | AA195: 0 | AB195: 0 | AD195: 0 | AI195: 0 | AJ195: X | AN195: D | AR195: 0 | AT195: DMC_Z00540RF | AU195: 46275 | AV195: 0.60354167
